Workbook
Name Cycle_Date: 'Reload Status'!$C$1
Name Process_Date: 'Reload Status'!$D$1
Name TenMinutes: '[1]RPPS Chart'!$C$2
Name ThirtyMinutes: '[1]RPPS Chart'!$D$2

Sheet Daily_Completion Status
A1: OWNER | B1: PROCESS_TYPE | C1: TABLE_NAME | D1: PROCESS_DATE | E1: FINISH_DATE_TIME | F1: Key | G1: Process Date | H1: Finish DateTime
A2: DEN | B2: UPDATE | C2: PAC_ACCOUNT | D2: 2021-01-29 | E2: 2021-01-28 20:36:12 | F2: =DailyCompletionTable[[#This Row],[TABLE_NAME]]&DailyCompletionTable[[#This Row],[PROCESS_DATE]] -> PAC_ACCOUNT2021-01-29 | G2: =DATE(LEFT(DailyCompletionTable[[#This Row],[PROCESS_DATE]],4),MID(DailyCompletionTable[[#This Row],[PROCESS_DATE]],6,2),MID(DailyCompletionTable[[#This Row],[PROCESS_DATE]],9,2)) -> 44225 | H2: =DATE(LEFT(DailyCompletionTable[[#This Row],[FINISH_DATE_TIME]],4),MID(DailyCompletionTable[[#This Row],[FINISH_DATE_TIME]],6,2),MID(DailyCompletionTable[[#This Row],[FINISH_DATE_TIME]],9,2)) + TIME(MID(DailyCompletionTable[[#This Row],[FINISH_DATE_TIME]],12,2),MID(DailyCompletionTable[[#This Row],[FINISH_DATE_TIME]],15,2),MID(DailyCompletionTable[[#This Row],[FINISH_DATE_TIME]],18,2)) -> 44224.858
A3: DEN | B3: UPDATE | C3: PAG_AVAIL_GROUP | D3: 2021-01-29 | E3: 2021-01-28 20:36:12 | F3: =DailyCompletionTable[[#This Row],[TABLE_NAME]]&DailyCompletionTable[[#This Row],[PROCESS_DATE]] -> PAG_AVAIL_GROUP2021-01-29 | G3: =DATE(LEFT(DailyCompletionTable[[#This Row],[PROCESS_DATE]],4),MID(DailyCompletionTable[[#This Row],[PROCESS_DATE]],6,2),MID(DailyCompletionTable[[#This Row],[PROCESS_DATE]],9,2)) -> 44225 | H3: =DATE(LEFT(DailyCompletionTable[[#This Row],[FINISH_DATE_TIME]],4),MID(DailyCompletionTable[[#This Row],[FINISH_DATE_TIME]],6,2),MID(DailyCompletionTable[[#This Row],[FINISH_DATE_TIME]],9,2)) + TIME(MID(DailyCompletionTable[[#This Row],[FINISH_DATE_TIME]],12,2),MID(DailyCompletionTable[[#This Row],[FINISH_DATE_TIME]],15,2),MID(DailyCompletionTable[[#This Row],[FINISH_DATE_TIME]],18,2)) -> 44224.858
A4: DEN | B4: UPDATE | C4: PAP_AITM_PARM_VAL | D4: 2021-01-29 | E4: 2021-01-28 20:36:12 | F4: =DailyCompletionTable[[#This Row],[TABLE_NAME]]&DailyCompletionTable[[#This Row],[PROCESS_DATE]] -> PAP_AITM_PARM_VAL2021-01-29 | G4: =DATE(LEFT(DailyCompletionTable[[#This Row],[PROCESS_DATE]],4),MID(DailyCompletionTable[[#This Row],[PROCESS_DATE]],6,2),MID(DailyCompletionTable[[#This Row],[PROCESS_DATE]],9,2)) -> 44225 | H4: =DATE(LEFT(DailyCompletionTable[[#This Row],[FINISH_DATE_TIME]],4),MID(DailyCompletionTable[[#This Row],[FINISH_DATE_TIME]],6,2),MID(DailyCompletionTable[[#This Row],[FINISH_DATE_TIME]],9,2)) + TIME(MID(DailyCompletionTable[[#This Row],[FINISH_DATE_TIME]],12,2),MID(DailyCompletionTable[[#This Row],[FINISH_DATE_TIME]],15,2),MID(DailyCompletionTable[[#This Row],[FINISH_DATE_TIME]],18,2)) -> 44224.858
A5: DEN | B5: UPDATE | C5: PAS_ACCT_SERV_ITM | D5: 2021-01-29 | E5: 2021-01-28 20:36:12 | F5: =DailyCompletionTable[[#This Row],[TABLE_NAME]]&DailyCompletionTable[[#This Row],[PROCESS_DATE]] -> PAS_ACCT_SERV_ITM2021-01-29 | G5: =DATE(LEFT(DailyCompletionTable[[#This Row],[PROCESS_DATE]],4),MID(DailyCompletionTable[[#This Row],[PROCESS_DATE]],6,2),MID(DailyCompletionTable[[#This Row],[PROCESS_DATE]],9,2)) -> 44225 | H5: =DATE(LEFT(DailyCompletionTable[[#This Row],[FINISH_DATE_TIME]],4),MID(DailyCompletionTable[[#This Row],[FINISH_DATE_TIME]],6,2),MID(DailyCompletionTable[[#This Row],[FINISH_DATE_TIME]],9,2)) + TIME(MID(DailyCompletionTable[[#This Row],[FINISH_DATE_TIME]],12,2),MID(DailyCompletionTable[[#This Row],[FINISH_DATE_TIME]],15,2),MID(DailyCompletionTable[[#This Row],[FINISH_DATE_TIME]],18,2)) -> 44224.858
A6: DEN | B6: UPDATE | C6: PAT_AVAIL_CATG | D6: 2021-01-29 | E6: 2021-01-28 20:36:12 | F6: =DailyCompletionTable[[#This Row],[TABLE_NAME]]&DailyCompletionTable[[#This Row],[PROCESS_DATE]] -> PAT_AVAIL_CATG2021-01-29 | G6: =DATE(LEFT(DailyCompletionTable[[#This Row],[PROCESS_DATE]],4),MID(DailyCompletionTable[[#This Row],[PROCESS_DATE]],6,2),MID(DailyCompletionTable[[#This Row],[PROCESS_DATE]],9,2)) -> 44225 | H6: =DATE(LEFT(DailyCompletionTable[[#This Row],[FINISH_DATE_TIME]],4),MID(DailyCompletionTable[[#This Row],[FINISH_DATE_TIME]],6,2),MID(DailyCompletionTable[[#This Row],[FINISH_DATE_TIME]],9,2)) + TIME(MID(DailyCompletionTable[[#This Row],[FINISH_DATE_TIME]],12,2),MID(DailyCompletionTable[[#This Row],[FINISH_DATE_TIME]],15,2),MID(DailyCompletionTable[[#This Row],[FINISH_DATE_TIME]],18,2)) -> 44224.858
A7: DEN | B7: UPDATE | C7: PBK_TN_BLOCK | D7: 2021-01-29 | E7: 2021-01-28 20:36:12 | F7: =DailyCompletionTable[[#This Row],[TABLE_NAME]]&DailyCompletionTable[[#This Row],[PROCESS_DATE]] -> PBK_TN_BLOCK2021-01-29 | G7: =DATE(LEFT(DailyCompletionTable[[#This Row],[PROCESS_DATE]],4),MID(DailyCompletionTable[[#This Row],[PROCESS_DATE]],6,2),MID(DailyCompletionTable[[#This Row],[PROCESS_DATE]],9,2)) -> 44225 | H7: =DATE(LEFT(DailyCompletionTable[[#This Row],[FINISH_DATE_TIME]],4),MID(DailyCompletionTable[[#This Row],[FINISH_DATE_TIME]],6,2),MID(DailyCompletionTable[[#This Row],[FINISH_DATE_TIME]],9,2)) + TIME(MID(DailyCompletionTable[[#This Row],[FINISH_DATE_TIME]],12,2),MID(DailyCompletionTable[[#This Row],[FINISH_DATE_TIME]],15,2),MID(DailyCompletionTable[[#This Row],[FINISH_DATE_TIME]],18,2)) -> 44224.858
A8: DEN | B8: UPDATE | C8: PC | D8: 2021-01-29 | E8: 2021-01-28 21:46:01 | F8: =DailyCompletionTable[[#This Row],[TABLE_NAME]]&DailyCompletionTable[[#This Row],[PROCESS_DATE]] -> PC2021-01-29 | G8: =DATE(LEFT(DailyCompletionTable[[#This Row],[PROCESS_DATE]],4),MID(DailyCompletionTable[[#This Row],[PROCESS_DATE]],6,2),MID(DailyCompletionTable[[#This Row],[PROCESS_DATE]],9,2)) -> 44225 | H8: =DATE(LEFT(DailyCompletionTable[[#This Row],[FINISH_DATE_TIME]],4),MID(DailyCompletionTable[[#This Row],[FINISH_DATE_TIME]],6,2),MID(DailyCompletionTable[[#This Row],[FINISH_DATE_TIME]],9,2)) + TIME(MID(DailyCompletionTable[[#This Row],[FINISH_DATE_TIME]],12,2),MID(DailyCompletionTable[[#This Row],[FINISH_DATE_TIME]],15,2),MID(DailyCompletionTable[[#This Row],[FINISH_DATE_TIME]],18,2)) -> 44224.907
A9: DEN | B9: UPDATE | C9: PCA_CATG_ASSC | D9: 2021-01-29 | E9: 2021-01-28 20:15:49 | F9: =DailyCompletionTable[[#This Row],[TABLE_NAME]]&DailyCompletionTable[[#This Row],[PROCESS_DATE]] -> PCA_CATG_ASSC2021-01-29 | G9: =DATE(LEFT(DailyCompletionTable[[#This Row],[PROCESS_DATE]],4),MID(DailyCompletionTable[[#This Row],[PROCESS_DATE]],6,2),MID(DailyCompletionTable[[#This Row],[PROCESS_DATE]],9,2)) -> 44225 | H9: =DATE(LEFT(DailyCompletionTable[[#This Row],[FINISH_DATE_TIME]],4),MID(DailyCompletionTable[[#This Row],[FINISH_DATE_TIME]],6,2),MID(DailyCompletionTable[[#This Row],[FINISH_DATE_TIME]],9,2)) + TIME(MID(DailyCompletionTable[[#This Row],[FINISH_DATE_TIME]],12,2),MID(DailyCompletionTable[[#This Row],[FINISH_DATE_TIME]],15,2),MID(DailyCompletionTable[[#This Row],[FINISH_DATE_TIME]],18,2)) -> 44224.844
A10: DEN | B10: UPDATE | C10: PCI_CALL_CRD_INV | D10: 2021-01-29 | E10: 2021-01-28 20:36:12 | F10: =DailyCompletionTable[[#This Row],[TABLE_NAME]]&DailyCompletionTable[[#This Row],[PROCESS_DATE]] -> PCI_CALL_CRD_INV2021-01-29 | G10: =DATE(LEFT(DailyCompletionTable[[#This Row],[PROCESS_DATE]],4),MID(DailyCompletionTable[[#This Row],[PROCESS_DATE]],6,2),MID(DailyCompletionTable[[#This Row],[PROCESS_DATE]],9,2)) -> 44225 | H10: =DATE(LEFT(DailyCompletionTable[[#This Row],[FINISH_DATE_TIME]],4),MID(DailyCompletionTable[[#This Row],[FINISH_DATE_TIME]],6,2),MID(DailyCompletionTable[[#This Row],[FINISH_DATE_TIME]],9,2)) + TIME(MID(DailyCompletionTable[[#This Row],[FINISH_DATE_TIME]],12,2),MID(DailyCompletionTable[[#This Row],[FINISH_DATE_TIME]],15,2),MID(DailyCompletionTable[[#This Row],[FINISH_DATE_TIME]],18,2)) -> 44224.858
A11: DEN | B11: UPDATE | C11: PCP_CATG_PARM | D11: 2021-01-29 | E11: 2021-01-28 20:15:49 | F11: =DailyCompletionTable[[#This Row],[TABLE_NAME]]&DailyCompletionTable[[#This Row],[PROCESS_DATE]] -> PCP_CATG_PARM2021-01-29 | G11: =DATE(LEFT(DailyCompletionTable[[#This Row],[PROCESS_DATE]],4),MID(DailyCompletionTable[[#This Row],[PROCESS_DATE]],6,2),MID(DailyCompletionTable[[#This Row],[PROCESS_DATE]],9,2)) -> 44225 | H11: =DATE(LEFT(DailyCompletionTable[[#This Row],[FINISH_DATE_TIME]],4),MID(DailyCompletionTable[[#This Row],[FINISH_DATE_TIME]],6,2),MID(DailyCompletionTable[[#This Row],[FINISH_DATE_TIME]],9,2)) + TIME(MID(DailyCompletionTable[[#This Row],[FINISH_DATE_TIME]],12,2),MID(DailyCompletionTable[[#This Row],[FINISH_DATE_TIME]],15,2),MID(DailyCompletionTable[[#This Row],[FINISH_DATE_TIME]],18,2)) -> 44224.844
A12: DEN | B12: UPDATE | C12: PCS_CCS_SPA | D12: 2021-01-29 | E12: 2021-01-28 20:36:12 | F12: =DailyCompletionTable[[#This Row],[TABLE_NAME]]&DailyCompletionTable[[#This Row],[PROCESS_DATE]] -> PCS_CCS_SPA2021-01-29 | G12: =DATE(LEFT(DailyCompletionTable[[#This Row],[PROCESS_DATE]],4),MID(DailyCompletionTable[[#This Row],[PROCESS_DATE]],6,2),MID(DailyCompletionTable[[#This Row],[PROCESS_DATE]],9,2)) -> 44225 | H12: =DATE(LEFT(DailyCompletionTable[[#This Row],[FINISH_DATE_TIME]],4),MID(DailyCompletionTable[[#This Row],[FINISH_DATE_TIME]],6,2),MID(DailyCompletionTable[[#This Row],[FINISH_DATE_TIME]],9,2)) + TIME(MID(DailyCompletionTable[[#This Row],[FINISH_DATE_TIME]],12,2),MID(DailyCompletionTable[[#This Row],[FINISH_DATE_TIME]],15,2),MID(DailyCompletionTable[[#This Row],[FINISH_DATE_TIME]],18,2)) -> 44224.858
A13: DEN | B13: UPDATE | C13: PCT_CATG_ITM | D13: 2021-01-29 | E13: 2021-01-28 20:15:49 | F13: =DailyCompletionTable[[#This Row],[TABLE_NAME]]&DailyCompletionTable[[#This Row],[PROCESS_DATE]] -> PCT_CATG_ITM2021-01-29 | G13: =DATE(LEFT(DailyCompletionTable[[#This Row],[PROCESS_DATE]],4),MID(DailyCompletionTable[[#This Row],[PROCESS_DATE]],6,2),MID(DailyCompletionTable[[#This Row],[PROCESS_DATE]],9,2)) -> 44225 | H13: =DATE(LEFT(DailyCompletionTable[[#This Row],[FINISH_DATE_TIME]],4),MID(DailyCompletionTable[[#This Row],[FINISH_DATE_TIME]],6,2),MID(DailyCompletionTable[[#This Row],[FINISH_DATE_TIME]],9,2)) + TIME(MID(DailyCompletionTable[[#This Row],[FINISH_DATE_TIME]],12,2),MID(DailyCompletionTable[[#This Row],[FINISH_DATE_TIME]],15,2),MID(DailyCompletionTable[[#This Row],[FINISH_DATE_TIME]],18,2)) -> 44224.844
... A663: WOM | B663: UPDATE | C663: VIPXPMT | D663: 2021-01-29 | E663: 2021-01-28 21:03:28 | F663: =DailyCompletionTable[[#This Row],[TABLE_NAME]]&DailyCompletionTable[[#This Row],[PROCESS_DATE]] -> VIPXPMT2021-01-29 | G663: =DATE(LEFT(DailyCompletionTable[[#This Row],[PROCESS_DATE]],4),MID(DailyCompletionTable[[#This Row],[PROCESS_DATE]],6,2),MID(DailyCompletionTable[[#This Row],[PROCESS_DATE]],9,2)) -> 44225 | H663: =DATE(LEFT(DailyCompletionTable[[#This Row],[FINISH_DATE_TIME]],4),MID(DailyCompletionTable[[#This Row],[FINISH_DATE_TIME]],6,2),MID(DailyCompletionTable[[#This Row],[FINISH_DATE_TIME]],9,2)) + TIME(MID(DailyCompletionTable[[#This Row],[FINISH_DATE_TIME]],12,2),MID(DailyCompletionTable[[#This Row],[FINISH_DATE_TIME]],15,2),MID(DailyCompletionTable[[#This Row],[FINISH_DATE_TIME]],18,2)) -> 44224.877

Sheet Infocast Autosys Job status
B1: Job Name | C1: Type | D1: Box Name | E1: Last Start | F1: Last End | G1: Status | H1: Exit
A2: SAND Prod - C01
A3: All Times are in US/Mountain
A4: Show / hide columns
A5: Refresh Job StatusSend Event
B6: Job Name | C6: Type | D6: Box Name | E6: Last Start | F6: Last End | G6: Status | H6: Exit
B7: VAN-INFOCAST-NDW-CEE-DLY | C7: BOX | E7: 44225.344 | F7: 44225.344 | G7: SUCCESS | H7: 0
B8: VAN-INFOCAST-NDW-CVT-DLY | C8: BOX | E8: 44225.347 | F8: 44225.347 | G8: SUCCESS | H8: 0
B9: VAN-INFOCAST-NDW-CC1-DLY | C9: BOX | E9: 44225.344 | F9: 44225.344 | G9: SUCCESS | H9: 0
B10: VAN-INFOCAST-NDW-OCI-DLY | C10: BOX | E10: 44224.948 | F10: 44224.96 | G10: SUCCESS | H10: 0
B11: VAN-INFOCAST-NDW-OHI-DLY | C11: BOX | E11: 44224.948 | F11: 44224.951 | G11: SUCCESS | H11: 0
B12: VAN-INFOCAST-NDW-OPI-DLY | C12: BOX | E12: 44224.948 | F12: 44224.951 | G12: SUCCESS | H12: 0
B13: VAN-INFOCAST-NDW-OCR-DLY | C13: BOX | E13: 44224.951 | F13: 44224.954 | G13: SUCCESS | H13: 0
B14: VAN-INFOCAST-NDW-OOR-DLY | C14: BOX | E14: 44224.951 | F14: 44224.954 | G14: SUCCESS | H14: 0
B15: VAN-INFOCAST-NDW-OTR-DLY | C15: BOX | E15: 44224.951 | F15: 44224.954 | G15: SUCCESS | H15: 0
B16: VAN-INFOCAST-NDW-JOB-DLY | C16: BOX | E16: 44224.955 | F16: 44224.959 | G16: SUCCESS | H16: 0
B17: VAN-INFOCAST-NDW-EQP-DLY | C17: BOX | E17: 44224.955 | F17: 44224.959 | G17: SUCCESS | H17: 0
B18: VAN-INFOCAST-NDW-HSE-DLY | C18: BOX | E18: 44224.955 | F18: 44224.959 | G18: SUCCESS | H18: 0
... B31: VAN-INFOCAST-NDW-OTL-DLY | C31: BOX | E31: 44224.976 | F31: 44224.977 | G31: SUCCESS | H31: 0
B32: VAN-INFOCAST-NDW-CAL-OCI-DLY | C32: BOX | D32: VAN-INFOCAST-NDW-OCI-DLY | E32: 44224.948 | F32: 44224.958 | G32: SUCCESS | H32: 0
B33: VAN-INFOCAST-NDW-CAL-OHI-DLY | C33: BOX | D33: VAN-INFOCAST-NDW-OHI-DLY | E33: 44224.948 | F33: 44224.95 | G33: SUCCESS | H33: 0
B34: VAN-INFOCAST-NDW-CAL-OPI-DLY | C34: BOX | D34: VAN-INFOCAST-NDW-OPI-DLY | E34: 44224.948 | F34: 44224.951 | G34: SUCCESS | H34: 0
B35: VAN-INFOCAST-NDW-CAL-JOB-DLY | C35: BOX | D35: VAN-INFOCAST-NDW-JOB-DLY | E35: 44224.955 | F35: 44224.958 | G35: SUCCESS | H35: 0
B36: VAN-INFOCAST-NDW-CAL-OJA-DLY | C36: BOX | D36: VAN-INFOCAST-NDW-OJA-DLY | E36: 44224.972 | F36: 44224.973 | G36: SUCCESS | H36: 0
B37: VAN-INFOCAST-NDW-CAL-OCR-DLY | C37: BOX | D37: VAN-INFOCAST-NDW-OCR-DLY | E37: 44224.951 | F37: 44224.953 | G37: SUCCESS | H37: 0
B38: VAN-INFOCAST-NDW-CAL-OOR-DLY | C38: BOX | D38: VAN-INFOCAST-NDW-OOR-DLY | E38: 44224.951 | F38: 44224.953 | G38: SUCCESS | H38: 0
B39: VAN-INFOCAST-NDW-CAL-OTR-DLY | C39: BOX | D39: VAN-INFOCAST-NDW-OTR-DLY | E39: 44224.951 | F39: 44224.953 | G39: SUCCESS | H39: 0
B40: VAN-INFOCAST-NDW-CAL-OCL-DLY | C40: BOX | D40: VAN-INFOCAST-NDW-OCL-DLY | E40: 44224.976 | F40: 44224.976 | G40: SUCCESS | H40: 0
B41: VAN-INFOCAST-NDW-CAL-OOL-DLY | C41: BOX | D41: VAN-INFOCAST-NDW-OOL-DLY | E41: 44224.976 | F41: 44224.976 | G41: SUCCESS | H41: 0
B42: VAN-INFOCAST-NDW-CAL-OTL-DLY | C42: BOX | D42: VAN-INFOCAST-NDW-OTL-DLY | E42: 44224.976 | F42: 44224.976 | G42: SUCCESS | H42: 0
B43: VAN-INFOCAST-NDW-CAL-CUS-DLY | C43: BOX | D43: VAN-INFOCAST-NDW-CUS-DLY | E43: 44224.955 | F43: 44224.958 | G43: SUCCESS | H43: 0
... B450: VAN-INFOCAST-NDW-FLA-OTR-DLY | C450: BOX | D450: VAN-INFOCAST-NDW-OTR-DLY | E450: 44224.951 | F450: 44224.954 | G450: SUCCESS | H450: 0

Sheet Reload Status
B1: Cycle Date: | C1: 44238 | D1: =Cycle_Date+1 -> 44239 | E1: <--Process Date | H1: Replace the formula-calculated status with the word 'Validated' once validation for a specific table is completed.
A3: MSO | B3: Subsystem | C3: Abbreviation | D3: Table | E3: Vantage View Name | F3: Forecasted Reload Completion Time (MT) | G3: Forecasted Reload Completion Time (CT) | H3: Vantage Table Reload Status | I3: Actual Completion time (MT) | J3: Actual Completion time (CT) | K3: DWH Infocast Jobname | L3: DWH Infocast Filename | M3: Forecasted DWH Infocast File Delivery Time (MT) | N3: DWH Infocast Status | O3: DWH Infocast File Actual Delivery Time (MT) | P3: DWH Infocast File Actual Delivery Time (CT) | S3: Update RPPS | T3: Reload RPPS
A4: DEN | B4: EQUIPMENT/NEQ | C4: NEQ | D4: =_xlfn.TEXTJOIN("",TRUE, "VIP",ReloadStatusTable[[#This Row],[Abbreviation]],"T") -> VIPNEQT | E4: NEQ_SUB | F4: 44238.938 | G4: =ReloadStatusTable[[#This Row],[Forecasted Reload Completion Time (MT)]]+1/24 -> 44238.979 | H4: =IF(ReloadStatusTable[[#This Row],[Actual Completion time (MT)]]="","not done yet","Complete") -> not done yet | I4: =_xlfn.XLOOKUP(CONCATENATE(ReloadStatusTable[[#This Row],[Table]],TEXT(Process_Date,"yyyy-mm-dd")),'Daily_Completion Status'!F:F,'Daily_Completion Status'!H:H,"",0) | J4: =ReloadStatusTable[[#This Row],[Actual Completion time (MT)]]+1/24 -> #VALUE! | K4: =_xlfn.TEXTJOIN("",TRUE, "VAN-INFOCAST-NDW-",ReloadStatusTable[[#This Row],[MSO]],"-",IF(ReloadStatusTable[[#This Row],[Abbreviation]]="HSB","HSE",IF(ReloadStatusTable[[#This Row],[Abbreviation]]="OJB","JOB",ReloadStatusTable[[#This Row],[Abbreviation]])),"-DLY") -> VAN-INFOCAST-NDW-DEN-NEQ-DLY | L4: ndwinfoc.infocastvntg.YYYY-MM-DD.HHMMSS.SSS.neq_sub.dat.gz.pgp | M4: 44239.021 | N4: =IF(ReloadStatusTable[[#This Row],[DWH Infocast Jobname]]="N/A","N/A",IF(ReloadStatusTable[[#This Row],[DWH Infocast File Actual Delivery Time (MT)]]="","not delivered yet","Delivered")) -> not delivered yet | O4: =IF(ReloadStatusTable[[#This Row],[DWH Infocast Jobname]]="N/A","N/A",IF(AND(_xlfn.XLOOKUP(ReloadStatusTable[[#This Row],[DWH Infocast Jobname]],'Infocast Autosys Job status'!B:B,'Infocast Autosys Job status'!F:F,"",0)>($C$1 + (18/24)),_xlfn.XLOOKUP(ReloadStatusTable[[#This Row],[DWH Infocast Jobname]],'Infocast Autosys Job status'!B:B,'Infocast Autosys Job status'!F:F,"",0)<($C$1 + 1 + (18/24))),_xlfn.XLOOKUP(ReloadStatusTable[[#This Row],[DWH Infocast Jobname]],'Infocast Autosys Job status'!B:B,'Infocast Autosys Job status'!F:F,"",0),"")) | P4: =ReloadStatusTable[[#This Row],[DWH Infocast File Actual Delivery Time (MT)]] + 1/24 -> #VALUE! | S4: 1400 | T4: 45000
A5: SLC | B5: EQUIPMENT/NEQ | C5: NEQ | D5: =_xlfn.TEXTJOIN("",TRUE, "VIP",ReloadStatusTable[[#This Row],[Abbreviation]],"T") -> VIPNEQT | E5: NEQ_SUB | F5: 44238.938 | G5: =ReloadStatusTable[[#This Row],[Forecasted Reload Completion Time (MT)]]+1/24 -> 44238.979 | H5: =IF(ReloadStatusTable[[#This Row],[Actual Completion time (MT)]]="","not done yet","Complete") -> not done yet | I5: =_xlfn.XLOOKUP(CONCATENATE(ReloadStatusTable[[#This Row],[Table]],TEXT(Process_Date,"yyyy-mm-dd")),'Daily_Completion Status'!F:F,'Daily_Completion Status'!H:H,"",0) | J5: =ReloadStatusTable[[#This Row],[Actual Completion time (MT)]]+1/24 -> #VALUE! | K5: =_xlfn.TEXTJOIN("",TRUE, "VAN-INFOCAST-NDW-",ReloadStatusTable[[#This Row],[MSO]],"-",IF(ReloadStatusTable[[#This Row],[Abbreviation]]="HSB","HSE",IF(ReloadStatusTable[[#This Row],[Abbreviation]]="OJB","JOB",ReloadStatusTable[[#This Row],[Abbreviation]])),"-DLY") -> VAN-INFOCAST-NDW-SLC-NEQ-DLY | L5: ndwinfoc.infocastvntg.YYYY-MM-DD.HHMMSS.SSS.neq_sub.dat.gz.pgp | M5: 44239.021 | N5: =IF(ReloadStatusTable[[#This Row],[DWH Infocast Jobname]]="N/A","N/A",IF(ReloadStatusTable[[#This Row],[DWH Infocast File Actual Delivery Time (MT)]]="","not delivered yet","Delivered")) -> not delivered yet | O5: =IF(ReloadStatusTable[[#This Row],[DWH Infocast Jobname]]="N/A","N/A",IF(AND(_xlfn.XLOOKUP(ReloadStatusTable[[#This Row],[DWH Infocast Jobname]],'Infocast Autosys Job status'!B:B,'Infocast Autosys Job status'!F:F,"",0)>($C$1 + (18/24)),_xlfn.XLOOKUP(ReloadStatusTable[[#This Row],[DWH Infocast Jobname]],'Infocast Autosys Job status'!B:B,'Infocast Autosys Job status'!F:F,"",0)<($C$1 + 1 + (18/24))),_xlfn.XLOOKUP(ReloadStatusTable[[#This Row],[DWH Infocast Jobname]],'Infocast Autosys Job status'!B:B,'Infocast Autosys Job status'!F:F,"",0),"")) | P5: =ReloadStatusTable[[#This Row],[DWH Infocast File Actual Delivery Time (MT)]] + 1/24 -> #VALUE! | S5: 1400 | T5: 45000
A6: WOM | B6: EQUIPMENT/NEQ | C6: NEQ | D6: =_xlfn.TEXTJOIN("",TRUE, "VIP",ReloadStatusTable[[#This Row],[Abbreviation]],"T") -> VIPNEQT | E6: NEQ_SUB | F6: 44238.938 | G6: =ReloadStatusTable[[#This Row],[Forecasted Reload Completion Time (MT)]]+1/24 -> 44238.979 | H6: =IF(ReloadStatusTable[[#This Row],[Actual Completion time (MT)]]="","not done yet","Complete") -> not done yet | I6: =_xlfn.XLOOKUP(CONCATENATE(ReloadStatusTable[[#This Row],[Table]],TEXT(Process_Date,"yyyy-mm-dd")),'Daily_Completion Status'!F:F,'Daily_Completion Status'!H:H,"",0) | J6: =ReloadStatusTable[[#This Row],[Actual Completion time (MT)]]+1/24 -> #VALUE! | K6: =_xlfn.TEXTJOIN("",TRUE, "VAN-INFOCAST-NDW-",ReloadStatusTable[[#This Row],[MSO]],"-",IF(ReloadStatusTable[[#This Row],[Abbreviation]]="HSB","HSE",IF(ReloadStatusTable[[#This Row],[Abbreviation]]="OJB","JOB",ReloadStatusTable[[#This Row],[Abbreviation]])),"-DLY") -> VAN-INFOCAST-NDW-WOM-NEQ-DLY | L6: ndwinfoc.infocastvntg.YYYY-MM-DD.HHMMSS.SSS.neq_sub.dat.gz.pgp | M6: 44239.021 | N6: =IF(ReloadStatusTable[[#This Row],[DWH Infocast Jobname]]="N/A","N/A",IF(ReloadStatusTable[[#This Row],[DWH Infocast File Actual Delivery Time (MT)]]="","not delivered yet","Delivered")) -> not delivered yet | O6: =IF(ReloadStatusTable[[#This Row],[DWH Infocast Jobname]]="N/A","N/A",IF(AND(_xlfn.XLOOKUP(ReloadStatusTable[[#This Row],[DWH Infocast Jobname]],'Infocast Autosys Job status'!B:B,'Infocast Autosys Job status'!F:F,"",0)>($C$1 + (18/24)),_xlfn.XLOOKUP(ReloadStatusTable[[#This Row],[DWH Infocast Jobname]],'Infocast Autosys Job status'!B:B,'Infocast Autosys Job status'!F:F,"",0)<($C$1 + 1 + (18/24))),_xlfn.XLOOKUP(ReloadStatusTable[[#This Row],[DWH Infocast Jobname]],'Infocast Autosys Job status'!B:B,'Infocast Autosys Job status'!F:F,"",0),"")) | P6: =ReloadStatusTable[[#This Row],[DWH Infocast File Actual Delivery Time (MT)]] + 1/24 -> #VALUE! | S6: 1400 | T6: 45000
A7: DEN | B7: CONTACT | C7: CON | D7: =_xlfn.TEXTJOIN("",TRUE, "VIP",ReloadStatusTable[[#This Row],[Abbreviation]],"T") -> VIPCONT | E7: CON_CONTACT | F7: 44238.917 | G7: =ReloadStatusTable[[#This Row],[Forecasted Reload Completion Time (MT)]]+1/24 -> 44238.958 | H7: =IF(ReloadStatusTable[[#This Row],[Actual Completion time (MT)]]="","not done yet","Complete") -> not done yet | I7: =_xlfn.XLOOKUP(CONCATENATE(ReloadStatusTable[[#This Row],[Table]],TEXT(Process_Date,"yyyy-mm-dd")),'Daily_Completion Status'!F:F,'Daily_Completion Status'!H:H,"",0) | J7: =ReloadStatusTable[[#This Row],[Actual Completion time (MT)]]+1/24 -> #VALUE! | K7: =_xlfn.TEXTJOIN("",TRUE, "VAN-INFOCAST-NDW-",ReloadStatusTable[[#This Row],[MSO]],"-",IF(ReloadStatusTable[[#This Row],[Abbreviation]]="HSB","HSE",IF(ReloadStatusTable[[#This Row],[Abbreviation]]="OJB","JOB",ReloadStatusTable[[#This Row],[Abbreviation]])),"-DLY") -> VAN-INFOCAST-NDW-DEN-CON-DLY | L7: N/A | M7: N/A | N7: =IF(ReloadStatusTable[[#This Row],[DWH Infocast Jobname]]="N/A","N/A",IF(ReloadStatusTable[[#This Row],[DWH Infocast File Actual Delivery Time (MT)]]="","not delivered yet","Delivered")) -> not delivered yet | O7: =IF(ReloadStatusTable[[#This Row],[DWH Infocast Jobname]]="N/A","N/A",IF(AND(_xlfn.XLOOKUP(ReloadStatusTable[[#This Row],[DWH Infocast Jobname]],'Infocast Autosys Job status'!B:B,'Infocast Autosys Job status'!F:F,"",0)>($C$1 + (18/24)),_xlfn.XLOOKUP(ReloadStatusTable[[#This Row],[DWH Infocast Jobname]],'Infocast Autosys Job status'!B:B,'Infocast Autosys Job status'!F:F,"",0)<($C$1 + 1 + (18/24))),_xlfn.XLOOKUP(ReloadStatusTable[[#This Row],[DWH Infocast Jobname]],'Infocast Autosys Job status'!B:B,'Infocast Autosys Job status'!F:F,"",0),"")) | P7: =ReloadStatusTable[[#This Row],[DWH Infocast File Actual Delivery Time (MT)]] + 1/24 -> #VALUE!
A8: SLC | B8: CONTACT | C8: CON | D8: =_xlfn.TEXTJOIN("",TRUE, "VIP",ReloadStatusTable[[#This Row],[Abbreviation]],"T") -> VIPCONT | E8: CON_CONTACT | F8: 44238.917 | G8: =ReloadStatusTable[[#This Row],[Forecasted Reload Completion Time (MT)]]+1/24 -> 44238.958 | H8: =IF(ReloadStatusTable[[#This Row],[Actual Completion time (MT)]]="","not done yet","Complete") -> not done yet | I8: =_xlfn.XLOOKUP(CONCATENATE(ReloadStatusTable[[#This Row],[Table]],TEXT(Process_Date,"yyyy-mm-dd")),'Daily_Completion Status'!F:F,'Daily_Completion Status'!H:H,"",0) | J8: =ReloadStatusTable[[#This Row],[Actual Completion time (MT)]]+1/24 -> #VALUE! | K8: =_xlfn.TEXTJOIN("",TRUE, "VAN-INFOCAST-NDW-",ReloadStatusTable[[#This Row],[MSO]],"-",IF(ReloadStatusTable[[#This Row],[Abbreviation]]="HSB","HSE",IF(ReloadStatusTable[[#This Row],[Abbreviation]]="OJB","JOB",ReloadStatusTable[[#This Row],[Abbreviation]])),"-DLY") -> VAN-INFOCAST-NDW-SLC-CON-DLY | L8: N/A | M8: N/A | N8: =IF(ReloadStatusTable[[#This Row],[DWH Infocast Jobname]]="N/A","N/A",IF(ReloadStatusTable[[#This Row],[DWH Infocast File Actual Delivery Time (MT)]]="","not delivered yet","Delivered")) -> not delivered yet | O8: =IF(ReloadStatusTable[[#This Row],[DWH Infocast Jobname]]="N/A","N/A",IF(AND(_xlfn.XLOOKUP(ReloadStatusTable[[#This Row],[DWH Infocast Jobname]],'Infocast Autosys Job status'!B:B,'Infocast Autosys Job status'!F:F,"",0)>($C$1 + (18/24)),_xlfn.XLOOKUP(ReloadStatusTable[[#This Row],[DWH Infocast Jobname]],'Infocast Autosys Job status'!B:B,'Infocast Autosys Job status'!F:F,"",0)<($C$1 + 1 + (18/24))),_xlfn.XLOOKUP(ReloadStatusTable[[#This Row],[DWH Infocast Jobname]],'Infocast Autosys Job status'!B:B,'Infocast Autosys Job status'!F:F,"",0),"")) | P8: =ReloadStatusTable[[#This Row],[DWH Infocast File Actual Delivery Time (MT)]] + 1/24 -> #VALUE!
A9: WOM | B9: CONTACT | C9: CON | D9: =_xlfn.TEXTJOIN("",TRUE, "VIP",ReloadStatusTable[[#This Row],[Abbreviation]],"T") -> VIPCONT | E9: CON_CONTACT | F9: 44238.917 | G9: =ReloadStatusTable[[#This Row],[Forecasted Reload Completion Time (MT)]]+1/24 -> 44238.958 | H9: =IF(ReloadStatusTable[[#This Row],[Actual Completion time (MT)]]="","not done yet","Complete") -> not done yet | I9: =_xlfn.XLOOKUP(CONCATENATE(ReloadStatusTable[[#This Row],[Table]],TEXT(Process_Date,"yyyy-mm-dd")),'Daily_Completion Status'!F:F,'Daily_Completion Status'!H:H,"",0) | J9: =ReloadStatusTable[[#This Row],[Actual Completion time (MT)]]+1/24 -> #VALUE! | K9: =_xlfn.TEXTJOIN("",TRUE, "VAN-INFOCAST-NDW-",ReloadStatusTable[[#This Row],[MSO]],"-",IF(ReloadStatusTable[[#This Row],[Abbreviation]]="HSB","HSE",IF(ReloadStatusTable[[#This Row],[Abbreviation]]="OJB","JOB",ReloadStatusTable[[#This Row],[Abbreviation]])),"-DLY") -> VAN-INFOCAST-NDW-WOM-CON-DLY | L9: N/A | M9: N/A | N9: =IF(ReloadStatusTable[[#This Row],[DWH Infocast Jobname]]="N/A","N/A",IF(ReloadStatusTable[[#This Row],[DWH Infocast File Actual Delivery Time (MT)]]="","not delivered yet","Delivered")) -> not delivered yet | O9: =IF(ReloadStatusTable[[#This Row],[DWH Infocast Jobname]]="N/A","N/A",IF(AND(_xlfn.XLOOKUP(ReloadStatusTable[[#This Row],[DWH Infocast Jobname]],'Infocast Autosys Job status'!B:B,'Infocast Autosys Job status'!F:F,"",0)>($C$1 + (18/24)),_xlfn.XLOOKUP(ReloadStatusTable[[#This Row],[DWH Infocast Jobname]],'Infocast Autosys Job status'!B:B,'Infocast Autosys Job status'!F:F,"",0)<($C$1 + 1 + (18/24))),_xlfn.XLOOKUP(ReloadStatusTable[[#This Row],[DWH Infocast Jobname]],'Infocast Autosys Job status'!B:B,'Infocast Autosys Job status'!F:F,"",0),"")) | P9: =ReloadStatusTable[[#This Row],[DWH Infocast File Actual Delivery Time (MT)]] + 1/24 -> #VALUE!
A10: DEN | B10: HOUSE | C10: HSB | D10: =_xlfn.TEXTJOIN("",TRUE, "VIP",ReloadStatusTable[[#This Row],[Abbreviation]],"T") -> VIPHSBT | E10: HSE_BASE | F10: 44238.917 | G10: =ReloadStatusTable[[#This Row],[Forecasted Reload Completion Time (MT)]]+1/24 -> 44238.958 | H10: =IF(ReloadStatusTable[[#This Row],[Actual Completion time (MT)]]="","not done yet","Complete") -> not done yet | I10: =_xlfn.XLOOKUP(CONCATENATE(ReloadStatusTable[[#This Row],[Table]],TEXT(Process_Date,"yyyy-mm-dd")),'Daily_Completion Status'!F:F,'Daily_Completion Status'!H:H,"",0) | J10: =ReloadStatusTable[[#This Row],[Actual Completion time (MT)]]+1/24 -> #VALUE! | K10: =_xlfn.TEXTJOIN("",TRUE, "VAN-INFOCAST-NDW-",ReloadStatusTable[[#This Row],[MSO]],"-",IF(ReloadStatusTable[[#This Row],[Abbreviation]]="HSB","HSE",IF(ReloadStatusTable[[#This Row],[Abbreviation]]="OJB","JOB",ReloadStatusTable[[#This Row],[Abbreviation]])),"-DLY") -> VAN-INFOCAST-NDW-DEN-HSE-DLY | L10: ndwinfoc.infocastvntg.YYYY-MM-DD.HHMMSS.SSS.hse_base.dat.gz.pgp | M10: 44239.01 | N10: =IF(ReloadStatusTable[[#This Row],[DWH Infocast Jobname]]="N/A","N/A",IF(ReloadStatusTable[[#This Row],[DWH Infocast File Actual Delivery Time (MT)]]="","not delivered yet","Delivered")) -> not delivered yet | O10: =IF(ReloadStatusTable[[#This Row],[DWH Infocast Jobname]]="N/A","N/A",IF(AND(_xlfn.XLOOKUP(ReloadStatusTable[[#This Row],[DWH Infocast Jobname]],'Infocast Autosys Job status'!B:B,'Infocast Autosys Job status'!F:F,"",0)>($C$1 + (18/24)),_xlfn.XLOOKUP(ReloadStatusTable[[#This Row],[DWH Infocast Jobname]],'Infocast Autosys Job status'!B:B,'Infocast Autosys Job status'!F:F,"",0)<($C$1 + 1 + (18/24))),_xlfn.XLOOKUP(ReloadStatusTable[[#This Row],[DWH Infocast Jobname]],'Infocast Autosys Job status'!B:B,'Infocast Autosys Job status'!F:F,"",0),"")) | P10: =ReloadStatusTable[[#This Row],[DWH Infocast File Actual Delivery Time (MT)]] + 1/24 -> #VALUE!
A11: SLC | B11: HOUSE | C11: HSB | D11: =_xlfn.TEXTJOIN("",TRUE, "VIP",ReloadStatusTable[[#This Row],[Abbreviation]],"T") -> VIPHSBT | E11: HSE_BASE | F11: 44238.917 | G11: =ReloadStatusTable[[#This Row],[Forecasted Reload Completion Time (MT)]]+1/24 -> 44238.958 | H11: =IF(ReloadStatusTable[[#This Row],[Actual Completion time (MT)]]="","not done yet","Complete") -> not done yet | I11: =_xlfn.XLOOKUP(CONCATENATE(ReloadStatusTable[[#This Row],[Table]],TEXT(Process_Date,"yyyy-mm-dd")),'Daily_Completion Status'!F:F,'Daily_Completion Status'!H:H,"",0) | J11: =ReloadStatusTable[[#This Row],[Actual Completion time (MT)]]+1/24 -> #VALUE! | K11: =_xlfn.TEXTJOIN("",TRUE, "VAN-INFOCAST-NDW-",ReloadStatusTable[[#This Row],[MSO]],"-",IF(ReloadStatusTable[[#This Row],[Abbreviation]]="HSB","HSE",IF(ReloadStatusTable[[#This Row],[Abbreviation]]="OJB","JOB",ReloadStatusTable[[#This Row],[Abbreviation]])),"-DLY") -> VAN-INFOCAST-NDW-SLC-HSE-DLY | L11: ndwinfoc.infocastvntg.YYYY-MM-DD.HHMMSS.SSS.hse_base.dat.gz.pgp | M11: 44239.01 | N11: =IF(ReloadStatusTable[[#This Row],[DWH Infocast Jobname]]="N/A","N/A",IF(ReloadStatusTable[[#This Row],[DWH Infocast File Actual Delivery Time (MT)]]="","not delivered yet","Delivered")) -> not delivered yet | O11: =IF(ReloadStatusTable[[#This Row],[DWH Infocast Jobname]]="N/A","N/A",IF(AND(_xlfn.XLOOKUP(ReloadStatusTable[[#This Row],[DWH Infocast Jobname]],'Infocast Autosys Job status'!B:B,'Infocast Autosys Job status'!F:F,"",0)>($C$1 + (18/24)),_xlfn.XLOOKUP(ReloadStatusTable[[#This Row],[DWH Infocast Jobname]],'Infocast Autosys Job status'!B:B,'Infocast Autosys Job status'!F:F,"",0)<($C$1 + 1 + (18/24))),_xlfn.XLOOKUP(ReloadStatusTable[[#This Row],[DWH Infocast Jobname]],'Infocast Autosys Job status'!B:B,'Infocast Autosys Job status'!F:F,"",0),"")) | P11: =ReloadStatusTable[[#This Row],[DWH Infocast File Actual Delivery Time (MT)]] + 1/24 -> #VALUE!
A12: WOM | B12: HOUSE | C12: HSB | D12: =_xlfn.TEXTJOIN("",TRUE, "VIP",ReloadStatusTable[[#This Row],[Abbreviation]],"T") -> VIPHSBT | E12: HSE_BASE | F12: 44238.917 | G12: =ReloadStatusTable[[#This Row],[Forecasted Reload Completion Time (MT)]]+1/24 -> 44238.958 | H12: =IF(ReloadStatusTable[[#This Row],[Actual Completion time (MT)]]="","not done yet","Complete") -> not done yet | I12: =_xlfn.XLOOKUP(CONCATENATE(ReloadStatusTable[[#This Row],[Table]],TEXT(Process_Date,"yyyy-mm-dd")),'Daily_Completion Status'!F:F,'Daily_Completion Status'!H:H,"",0) | J12: =ReloadStatusTable[[#This Row],[Actual Completion time (MT)]]+1/24 -> #VALUE! | K12: =_xlfn.TEXTJOIN("",TRUE, "VAN-INFOCAST-NDW-",ReloadStatusTable[[#This Row],[MSO]],"-",IF(ReloadStatusTable[[#This Row],[Abbreviation]]="HSB","HSE",IF(ReloadStatusTable[[#This Row],[Abbreviation]]="OJB","JOB",ReloadStatusTable[[#This Row],[Abbreviation]])),"-DLY") -> VAN-INFOCAST-NDW-WOM-HSE-DLY | L12: ndwinfoc.infocastvntg.YYYY-MM-DD.HHMMSS.SSS.hse_base.dat.gz.pgp | M12: 44239.01 | N12: =IF(ReloadStatusTable[[#This Row],[DWH Infocast Jobname]]="N/A","N/A",IF(ReloadStatusTable[[#This Row],[DWH Infocast File Actual Delivery Time (MT)]]="","not delivered yet","Delivered")) -> not delivered yet | O12: =IF(ReloadStatusTable[[#This Row],[DWH Infocast Jobname]]="N/A","N/A",IF(AND(_xlfn.XLOOKUP(ReloadStatusTable[[#This Row],[DWH Infocast Jobname]],'Infocast Autosys Job status'!B:B,'Infocast Autosys Job status'!F:F,"",0)>($C$1 + (18/24)),_xlfn.XLOOKUP(ReloadStatusTable[[#This Row],[DWH Infocast Jobname]],'Infocast Autosys Job status'!B:B,'Infocast Autosys Job status'!F:F,"",0)<($C$1 + 1 + (18/24))),_xlfn.XLOOKUP(ReloadStatusTable[[#This Row],[DWH Infocast Jobname]],'Infocast Autosys Job status'!B:B,'Infocast Autosys Job status'!F:F,"",0),"")) | P12: =ReloadStatusTable[[#This Row],[DWH Infocast File Actual Delivery Time (MT)]] + 1/24 -> #VALUE!
A13: DEN | B13: HOUSE | C13: HSL | D13: =_xlfn.TEXTJOIN("",TRUE, "VIP",ReloadStatusTable[[#This Row],[Abbreviation]],"T") -> VIPHSLT | E13: HSL_LOB | F13: 44238.917 | G13: =ReloadStatusTable[[#This Row],[Forecasted Reload Completion Time (MT)]]+1/24 -> 44238.958 | H13: =IF(ReloadStatusTable[[#This Row],[Actual Completion time (MT)]]="","not done yet","Complete") -> not done yet | I13: =_xlfn.XLOOKUP(CONCATENATE(ReloadStatusTable[[#This Row],[Table]],TEXT(Process_Date,"yyyy-mm-dd")),'Daily_Completion Status'!F:F,'Daily_Completion Status'!H:H,"",0) | J13: =ReloadStatusTable[[#This Row],[Actual Completion time (MT)]]+1/24 -> #VALUE! | K13: =_xlfn.TEXTJOIN("",TRUE, "VAN-INFOCAST-NDW-",ReloadStatusTable[[#This Row],[MSO]],"-",IF(ReloadStatusTable[[#This Row],[Abbreviation]]="HSB","HSE",IF(ReloadStatusTable[[#This Row],[Abbreviation]]="OJB","JOB",ReloadStatusTable[[#This Row],[Abbreviation]])),"-DLY") -> VAN-INFOCAST-NDW-DEN-HSL-DLY | L13: ndwinfoc.infocastvntg.YYYY-MM-DD.HHMMSS.SSS.hsl_lob.dat.gz.pgp | M13: 44239.01 | N13: =IF(ReloadStatusTable[[#This Row],[DWH Infocast Jobname]]="N/A","N/A",IF(ReloadStatusTable[[#This Row],[DWH Infocast File Actual Delivery Time (MT)]]="","not delivered yet","Delivered")) -> not delivered yet | O13: =IF(ReloadStatusTable[[#This Row],[DWH Infocast Jobname]]="N/A","N/A",IF(AND(_xlfn.XLOOKUP(ReloadStatusTable[[#This Row],[DWH Infocast Jobname]],'Infocast Autosys Job status'!B:B,'Infocast Autosys Job status'!F:F,"",0)>($C$1 + (18/24)),_xlfn.XLOOKUP(ReloadStatusTable[[#This Row],[DWH Infocast Jobname]],'Infocast Autosys Job status'!B:B,'Infocast Autosys Job status'!F:F,"",0)<($C$1 + 1 + (18/24))),_xlfn.XLOOKUP(ReloadStatusTable[[#This Row],[DWH Infocast Jobname]],'Infocast Autosys Job status'!B:B,'Infocast Autosys Job status'!F:F,"",0),"")) | P13: =ReloadStatusTable[[#This Row],[DWH Infocast File Actual Delivery Time (MT)]] + 1/24 -> #VALUE!
A14: SLC | B14: HOUSE | C14: HSL | D14: =_xlfn.TEXTJOIN("",TRUE, "VIP",ReloadStatusTable[[#This Row],[Abbreviation]],"T") -> VIPHSLT | E14: HSL_LOB | F14: 44238.917 | G14: =ReloadStatusTable[[#This Row],[Forecasted Reload Completion Time (MT)]]+1/24 -> 44238.958 | H14: =IF(ReloadStatusTable[[#This Row],[Actual Completion time (MT)]]="","not done yet","Complete") -> not done yet | I14: =_xlfn.XLOOKUP(CONCATENATE(ReloadStatusTable[[#This Row],[Table]],TEXT(Process_Date,"yyyy-mm-dd")),'Daily_Completion Status'!F:F,'Daily_Completion Status'!H:H,"",0) | J14: =ReloadStatusTable[[#This Row],[Actual Completion time (MT)]]+1/24 -> #VALUE! | K14: =_xlfn.TEXTJOIN("",TRUE, "VAN-INFOCAST-NDW-",ReloadStatusTable[[#This Row],[MSO]],"-",IF(ReloadStatusTable[[#This Row],[Abbreviation]]="HSB","HSE",IF(ReloadStatusTable[[#This Row],[Abbreviation]]="OJB","JOB",ReloadStatusTable[[#This Row],[Abbreviation]])),"-DLY") -> VAN-INFOCAST-NDW-SLC-HSL-DLY | L14: ndwinfoc.infocastvntg.YYYY-MM-DD.HHMMSS.SSS.hsl_lob.dat.gz.pgp | M14: 44239.01 | N14: =IF(ReloadStatusTable[[#This Row],[DWH Infocast Jobname]]="N/A","N/A",IF(ReloadStatusTable[[#This Row],[DWH Infocast File Actual Delivery Time (MT)]]="","not delivered yet","Delivered")) -> not delivered yet | O14: =IF(ReloadStatusTable[[#This Row],[DWH Infocast Jobname]]="N/A","N/A",IF(AND(_xlfn.XLOOKUP(ReloadStatusTable[[#This Row],[DWH Infocast Jobname]],'Infocast Autosys Job status'!B:B,'Infocast Autosys Job status'!F:F,"",0)>($C$1 + (18/24)),_xlfn.XLOOKUP(ReloadStatusTable[[#This Row],[DWH Infocast Jobname]],'Infocast Autosys Job status'!B:B,'Infocast Autosys Job status'!F:F,"",0)<($C$1 + 1 + (18/24))),_xlfn.XLOOKUP(ReloadStatusTable[[#This Row],[DWH Infocast Jobname]],'Infocast Autosys Job status'!B:B,'Infocast Autosys Job status'!F:F,"",0),"")) | P14: =ReloadStatusTable[[#This Row],[DWH Infocast File Actual Delivery Time (MT)]] + 1/24 -> #VALUE!
A15: WOM | B15: HOUSE | C15: HSL | D15: =_xlfn.TEXTJOIN("",TRUE, "VIP",ReloadStatusTable[[#This Row],[Abbreviation]],"T") -> VIPHSLT | E15: HSL_LOB | F15: 44238.917 | G15: =ReloadStatusTable[[#This Row],[Forecasted Reload Completion Time (MT)]]+1/24 -> 44238.958 | H15: =IF(ReloadStatusTable[[#This Row],[Actual Completion time (MT)]]="","not done yet","Complete") -> not done yet | I15: =_xlfn.XLOOKUP(CONCATENATE(ReloadStatusTable[[#This Row],[Table]],TEXT(Process_Date,"yyyy-mm-dd")),'Daily_Completion Status'!F:F,'Daily_Completion Status'!H:H,"",0) | J15: =ReloadStatusTable[[#This Row],[Actual Completion time (MT)]]+1/24 -> #VALUE! | K15: =_xlfn.TEXTJOIN("",TRUE, "VAN-INFOCAST-NDW-",ReloadStatusTable[[#This Row],[MSO]],"-",IF(ReloadStatusTable[[#This Row],[Abbreviation]]="HSB","HSE",IF(ReloadStatusTable[[#This Row],[Abbreviation]]="OJB","JOB",ReloadStatusTable[[#This Row],[Abbreviation]])),"-DLY") -> VAN-INFOCAST-NDW-WOM-HSL-DLY | L15: ndwinfoc.infocastvntg.YYYY-MM-DD.HHMMSS.SSS.hsl_lob.dat.gz.pgp | M15: 44239.01 | N15: =IF(ReloadStatusTable[[#This Row],[DWH Infocast Jobname]]="N/A","N/A",IF(ReloadStatusTable[[#This Row],[DWH Infocast File Actual Delivery Time (MT)]]="","not delivered yet","Delivered")) -> not delivered yet | O15: =IF(ReloadStatusTable[[#This Row],[DWH Infocast Jobname]]="N/A","N/A",IF(AND(_xlfn.XLOOKUP(ReloadStatusTable[[#This Row],[DWH Infocast Jobname]],'Infocast Autosys Job status'!B:B,'Infocast Autosys Job status'!F:F,"",0)>($C$1 + (18/24)),_xlfn.XLOOKUP(ReloadStatusTable[[#This Row],[DWH Infocast Jobname]],'Infocast Autosys Job status'!B:B,'Infocast Autosys Job status'!F:F,"",0)<($C$1 + 1 + (18/24))),_xlfn.XLOOKUP(ReloadStatusTable[[#This Row],[DWH Infocast Jobname]],'Infocast Autosys Job status'!B:B,'Infocast Autosys Job status'!F:F,"",0),"")) | P15: =ReloadStatusTable[[#This Row],[DWH Infocast File Actual Delivery Time (MT)]] + 1/24 -> #VALUE!
A16: DEN | B16: HOUSE | C16: HSM | D16: =_xlfn.TEXTJOIN("",TRUE, "VIP",ReloadStatusTable[[#This Row],[Abbreviation]],"T") -> VIPHSMT | E16: HSM_MEMO | F16: 44238.917 | G16: =ReloadStatusTable[[#This Row],[Forecasted Reload Completion Time (MT)]]+1/24 -> 44238.958 | H16: =IF(ReloadStatusTable[[#This Row],[Actual Completion time (MT)]]="","not done yet","Complete") -> not done yet | I16: =_xlfn.XLOOKUP(CONCATENATE(ReloadStatusTable[[#This Row],[Table]],TEXT(Process_Date,"yyyy-mm-dd")),'Daily_Completion Status'!F:F,'Daily_Completion Status'!H:H,"",0) | J16: =ReloadStatusTable[[#This Row],[Actual Completion time (MT)]]+1/24 -> #VALUE! | K16: =_xlfn.TEXTJOIN("",TRUE, "VAN-INFOCAST-NDW-",ReloadStatusTable[[#This Row],[MSO]],"-",IF(ReloadStatusTable[[#This Row],[Abbreviation]]="HSB","HSE",IF(ReloadStatusTable[[#This Row],[Abbreviation]]="OJB","JOB",ReloadStatusTable[[#This Row],[Abbreviation]])),"-DLY") -> VAN-INFOCAST-NDW-DEN-HSM-DLY | L16: ndwinfoc.infocastvntg.YYYY-MM-DD.HHMMSS.SSS.hsm_memo.dat.gz.pgp | M16: 44239.01 | N16: =IF(ReloadStatusTable[[#This Row],[DWH Infocast Jobname]]="N/A","N/A",IF(ReloadStatusTable[[#This Row],[DWH Infocast File Actual Delivery Time (MT)]]="","not delivered yet","Delivered")) -> not delivered yet | O16: =IF(ReloadStatusTable[[#This Row],[DWH Infocast Jobname]]="N/A","N/A",IF(AND(_xlfn.XLOOKUP(ReloadStatusTable[[#This Row],[DWH Infocast Jobname]],'Infocast Autosys Job status'!B:B,'Infocast Autosys Job status'!F:F,"",0)>($C$1 + (18/24)),_xlfn.XLOOKUP(ReloadStatusTable[[#This Row],[DWH Infocast Jobname]],'Infocast Autosys Job status'!B:B,'Infocast Autosys Job status'!F:F,"",0)<($C$1 + 1 + (18/24))),_xlfn.XLOOKUP(ReloadStatusTable[[#This Row],[DWH Infocast Jobname]],'Infocast Autosys Job status'!B:B,'Infocast Autosys Job status'!F:F,"",0),"")) | P16: =ReloadStatusTable[[#This Row],[DWH Infocast File Actual Delivery Time (MT)]] + 1/24 -> #VALUE!
A17: SLC | B17: HOUSE | C17: HSM | D17: =_xlfn.TEXTJOIN("",TRUE, "VIP",ReloadStatusTable[[#This Row],[Abbreviation]],"T") -> VIPHSMT | E17: HSM_MEMO | F17: 44238.917 | G17: =ReloadStatusTable[[#This Row],[Forecasted Reload Completion Time (MT)]]+1/24 -> 44238.958 | H17: =IF(ReloadStatusTable[[#This Row],[Actual Completion time (MT)]]="","not done yet","Complete") -> not done yet | I17: =_xlfn.XLOOKUP(CONCATENATE(ReloadStatusTable[[#This Row],[Table]],TEXT(Process_Date,"yyyy-mm-dd")),'Daily_Completion Status'!F:F,'Daily_Completion Status'!H:H,"",0) | J17: =ReloadStatusTable[[#This Row],[Actual Completion time (MT)]]+1/24 -> #VALUE! | K17: =_xlfn.TEXTJOIN("",TRUE, "VAN-INFOCAST-NDW-",ReloadStatusTable[[#This Row],[MSO]],"-",IF(ReloadStatusTable[[#This Row],[Abbreviation]]="HSB","HSE",IF(ReloadStatusTable[[#This Row],[Abbreviation]]="OJB","JOB",ReloadStatusTable[[#This Row],[Abbreviation]])),"-DLY") -> VAN-INFOCAST-NDW-SLC-HSM-DLY | L17: ndwinfoc.infocastvntg.YYYY-MM-DD.HHMMSS.SSS.hsm_memo.dat.gz.pgp | M17: 44239.01 | N17: =IF(ReloadStatusTable[[#This Row],[DWH Infocast Jobname]]="N/A","N/A",IF(ReloadStatusTable[[#This Row],[DWH Infocast File Actual Delivery Time (MT)]]="","not delivered yet","Delivered")) -> not delivered yet | O17: =IF(ReloadStatusTable[[#This Row],[DWH Infocast Jobname]]="N/A","N/A",IF(AND(_xlfn.XLOOKUP(ReloadStatusTable[[#This Row],[DWH Infocast Jobname]],'Infocast Autosys Job status'!B:B,'Infocast Autosys Job status'!F:F,"",0)>($C$1 + (18/24)),_xlfn.XLOOKUP(ReloadStatusTable[[#This Row],[DWH Infocast Jobname]],'Infocast Autosys Job status'!B:B,'Infocast Autosys Job status'!F:F,"",0)<($C$1 + 1 + (18/24))),_xlfn.XLOOKUP(ReloadStatusTable[[#This Row],[DWH Infocast Jobname]],'Infocast Autosys Job status'!B:B,'Infocast Autosys Job status'!F:F,"",0),"")) | P17: =ReloadStatusTable[[#This Row],[DWH Infocast File Actual Delivery Time (MT)]] + 1/24 -> #VALUE!
A18: WOM | B18: HOUSE | C18: HSM | D18: =_xlfn.TEXTJOIN("",TRUE, "VIP",ReloadStatusTable[[#This Row],[Abbreviation]],"T") -> VIPHSMT | E18: HSM_MEMO | F18: 44238.917 | G18: =ReloadStatusTable[[#This Row],[Forecasted Reload Completion Time (MT)]]+1/24 -> 44238.958 | H18: =IF(ReloadStatusTable[[#This Row],[Actual Completion time (MT)]]="","not done yet","Complete") -> not done yet | I18: =_xlfn.XLOOKUP(CONCATENATE(ReloadStatusTable[[#This Row],[Table]],TEXT(Process_Date,"yyyy-mm-dd")),'Daily_Completion Status'!F:F,'Daily_Completion Status'!H:H,"",0) | J18: =ReloadStatusTable[[#This Row],[Actual Completion time (MT)]]+1/24 -> #VALUE! | K18: =_xlfn.TEXTJOIN("",TRUE, "VAN-INFOCAST-NDW-",ReloadStatusTable[[#This Row],[MSO]],"-",IF(ReloadStatusTable[[#This Row],[Abbreviation]]="HSB","HSE",IF(ReloadStatusTable[[#This Row],[Abbreviation]]="OJB","JOB",ReloadStatusTable[[#This Row],[Abbreviation]])),"-DLY") -> VAN-INFOCAST-NDW-WOM-HSM-DLY | L18: ndwinfoc.infocastvntg.YYYY-MM-DD.HHMMSS.SSS.hsm_memo.dat.gz.pgp | M18: 44239.01 | N18: =IF(ReloadStatusTable[[#This Row],[DWH Infocast Jobname]]="N/A","N/A",IF(ReloadStatusTable[[#This Row],[DWH Infocast File Actual Delivery Time (MT)]]="","not delivered yet","Delivered")) -> not delivered yet | O18: =IF(ReloadStatusTable[[#This Row],[DWH Infocast Jobname]]="N/A","N/A",IF(AND(_xlfn.XLOOKUP(ReloadStatusTable[[#This Row],[DWH Infocast Jobname]],'Infocast Autosys Job status'!B:B,'Infocast Autosys Job status'!F:F,"",0)>($C$1 + (18/24)),_xlfn.XLOOKUP(ReloadStatusTable[[#This Row],[DWH Infocast Jobname]],'Infocast Autosys Job status'!B:B,'Infocast Autosys Job status'!F:F,"",0)<($C$1 + 1 + (18/24))),_xlfn.XLOOKUP(ReloadStatusTable[[#This Row],[DWH Infocast Jobname]],'Infocast Autosys Job status'!B:B,'Infocast Autosys Job status'!F:F,"",0),"")) | P18: =ReloadStatusTable[[#This Row],[DWH Infocast File Actual Delivery Time (MT)]] + 1/24 -> #VALUE!
A19: DEN | B19: PPV EVENT PURCHASE DETAIL | C19: EPD | D19: =_xlfn.TEXTJOIN("",TRUE, "VIP",ReloadStatusTable[[#This Row],[Abbreviation]],"T") -> VIPEPDT | E19: EPD_EVENT_PURCH_DETAIL | F19: 44238.896 | G19: =ReloadStatusTable[[#This Row],[Forecasted Reload Completion Time (MT)]]+1/24 -> 44238.938 | H19: =IF(ReloadStatusTable[[#This Row],[Actual Completion time (MT)]]="","not done yet","Complete") -> not done yet | I19: =_xlfn.XLOOKUP(CONCATENATE(ReloadStatusTable[[#This Row],[Table]],TEXT(Process_Date,"yyyy-mm-dd")),'Daily_Completion Status'!F:F,'Daily_Completion Status'!H:H,"",0) | J19: =ReloadStatusTable[[#This Row],[Actual Completion time (MT)]]+1/24 -> #VALUE! | K19: =_xlfn.TEXTJOIN("",TRUE, "VAN-INFOCAST-NDW-",ReloadStatusTable[[#This Row],[MSO]],"-",IF(ReloadStatusTable[[#This Row],[Abbreviation]]="HSB","HSE",IF(ReloadStatusTable[[#This Row],[Abbreviation]]="OJB","JOB",ReloadStatusTable[[#This Row],[Abbreviation]])),"-DLY") -> VAN-INFOCAST-NDW-DEN-EPD-DLY | L19: N/A | M19: N/A | N19: =IF(ReloadStatusTable[[#This Row],[DWH Infocast Jobname]]="N/A","N/A",IF(ReloadStatusTable[[#This Row],[DWH Infocast File Actual Delivery Time (MT)]]="","not delivered yet","Delivered")) -> not delivered yet | O19: =IF(ReloadStatusTable[[#This Row],[DWH Infocast Jobname]]="N/A","N/A",IF(AND(_xlfn.XLOOKUP(ReloadStatusTable[[#This Row],[DWH Infocast Jobname]],'Infocast Autosys Job status'!B:B,'Infocast Autosys Job status'!F:F,"",0)>($C$1 + (18/24)),_xlfn.XLOOKUP(ReloadStatusTable[[#This Row],[DWH Infocast Jobname]],'Infocast Autosys Job status'!B:B,'Infocast Autosys Job status'!F:F,"",0)<($C$1 + 1 + (18/24))),_xlfn.XLOOKUP(ReloadStatusTable[[#This Row],[DWH Infocast Jobname]],'Infocast Autosys Job status'!B:B,'Infocast Autosys Job status'!F:F,"",0),"")) | P19: =ReloadStatusTable[[#This Row],[DWH Infocast File Actual Delivery Time (MT)]] + 1/24 -> #VALUE!
A20: SLC | B20: PPV EVENT PURCHASE DETAIL | C20: EPD | D20: =_xlfn.TEXTJOIN("",TRUE, "VIP",ReloadStatusTable[[#This Row],[Abbreviation]],"T") -> VIPEPDT | E20: EPD_EVENT_PURCH_DETAIL | F20: 44238.896 | G20: =ReloadStatusTable[[#This Row],[Forecasted Reload Completion Time (MT)]]+1/24 -> 44238.938 | H20: =IF(ReloadStatusTable[[#This Row],[Actual Completion time (MT)]]="","not done yet","Complete") -> not done yet | I20: =_xlfn.XLOOKUP(CONCATENATE(ReloadStatusTable[[#This Row],[Table]],TEXT(Process_Date,"yyyy-mm-dd")),'Daily_Completion Status'!F:F,'Daily_Completion Status'!H:H,"",0) | J20: =ReloadStatusTable[[#This Row],[Actual Completion time (MT)]]+1/24 -> #VALUE! | K20: =_xlfn.TEXTJOIN("",TRUE, "VAN-INFOCAST-NDW-",ReloadStatusTable[[#This Row],[MSO]],"-",IF(ReloadStatusTable[[#This Row],[Abbreviation]]="HSB","HSE",IF(ReloadStatusTable[[#This Row],[Abbreviation]]="OJB","JOB",ReloadStatusTable[[#This Row],[Abbreviation]])),"-DLY") -> VAN-INFOCAST-NDW-SLC-EPD-DLY | L20: N/A | M20: N/A | N20: =IF(ReloadStatusTable[[#This Row],[DWH Infocast Jobname]]="N/A","N/A",IF(ReloadStatusTable[[#This Row],[DWH Infocast File Actual Delivery Time (MT)]]="","not delivered yet","Delivered")) -> not delivered yet | O20: =IF(ReloadStatusTable[[#This Row],[DWH Infocast Jobname]]="N/A","N/A",IF(AND(_xlfn.XLOOKUP(ReloadStatusTable[[#This Row],[DWH Infocast Jobname]],'Infocast Autosys Job status'!B:B,'Infocast Autosys Job status'!F:F,"",0)>($C$1 + (18/24)),_xlfn.XLOOKUP(ReloadStatusTable[[#This Row],[DWH Infocast Jobname]],'Infocast Autosys Job status'!B:B,'Infocast Autosys Job status'!F:F,"",0)<($C$1 + 1 + (18/24))),_xlfn.XLOOKUP(ReloadStatusTable[[#This Row],[DWH Infocast Jobname]],'Infocast Autosys Job status'!B:B,'Infocast Autosys Job status'!F:F,"",0),"")) | P20: =ReloadStatusTable[[#This Row],[DWH Infocast File Actual Delivery Time (MT)]] + 1/24 -> #VALUE!
A21: WOM | B21: PPV EVENT PURCHASE DETAIL | C21: EPD | D21: =_xlfn.TEXTJOIN("",TRUE, "VIP",ReloadStatusTable[[#This Row],[Abbreviation]],"T") -> VIPEPDT | E21: EPD_EVENT_PURCH_DETAIL | F21: 44238.896 | G21: =ReloadStatusTable[[#This Row],[Forecasted Reload Completion Time (MT)]]+1/24 -> 44238.938 | H21: =IF(ReloadStatusTable[[#This Row],[Actual Completion time (MT)]]="","not done yet","Complete") -> not done yet | I21: =_xlfn.XLOOKUP(CONCATENATE(ReloadStatusTable[[#This Row],[Table]],TEXT(Process_Date,"yyyy-mm-dd")),'Daily_Completion Status'!F:F,'Daily_Completion Status'!H:H,"",0) | J21: =ReloadStatusTable[[#This Row],[Actual Completion time (MT)]]+1/24 -> #VALUE! | K21: =_xlfn.TEXTJOIN("",TRUE, "VAN-INFOCAST-NDW-",ReloadStatusTable[[#This Row],[MSO]],"-",IF(ReloadStatusTable[[#This Row],[Abbreviation]]="HSB","HSE",IF(ReloadStatusTable[[#This Row],[Abbreviation]]="OJB","JOB",ReloadStatusTable[[#This Row],[Abbreviation]])),"-DLY") -> VAN-INFOCAST-NDW-WOM-EPD-DLY | L21: N/A | M21: N/A | N21: =IF(ReloadStatusTable[[#This Row],[DWH Infocast Jobname]]="N/A","N/A",IF(ReloadStatusTable[[#This Row],[DWH Infocast File Actual Delivery Time (MT)]]="","not delivered yet","Delivered")) -> not delivered yet | O21: =IF(ReloadStatusTable[[#This Row],[DWH Infocast Jobname]]="N/A","N/A",IF(AND(_xlfn.XLOOKUP(ReloadStatusTable[[#This Row],[DWH Infocast Jobname]],'Infocast Autosys Job status'!B:B,'Infocast Autosys Job status'!F:F,"",0)>($C$1 + (18/24)),_xlfn.XLOOKUP(ReloadStatusTable[[#This Row],[DWH Infocast Jobname]],'Infocast Autosys Job status'!B:B,'Infocast Autosys Job status'!F:F,"",0)<($C$1 + 1 + (18/24))),_xlfn.XLOOKUP(ReloadStatusTable[[#This Row],[DWH Infocast Jobname]],'Infocast Autosys Job status'!B:B,'Infocast Autosys Job status'!F:F,"",0),"")) | P21: =ReloadStatusTable[[#This Row],[DWH Infocast File Actual Delivery Time (MT)]] + 1/24 -> #VALUE!
A22: DEN | B22: ACP ORDER/JOB AUDIT | C22: OAJ | D22: =_xlfn.TEXTJOIN("",TRUE, "VIP",ReloadStatusTable[[#This Row],[Abbreviation]],"T") -> VIPOAJT | E22: OAJ_AUDIT | F22: 44238.896 | G22: =ReloadStatusTable[[#This Row],[Forecasted Reload Completion Time (MT)]]+1/24 -> 44238.938 | H22: =IF(ReloadStatusTable[[#This Row],[Actual Completion time (MT)]]="","not done yet","Complete") -> not done yet | I22: =_xlfn.XLOOKUP(CONCATENATE(ReloadStatusTable[[#This Row],[Table]],TEXT(Process_Date,"yyyy-mm-dd")),'Daily_Completion Status'!F:F,'Daily_Completion Status'!H:H,"",0) | J22: =ReloadStatusTable[[#This Row],[Actual Completion time (MT)]]+1/24 -> #VALUE! | K22: =_xlfn.TEXTJOIN("",TRUE, "VAN-INFOCAST-NDW-",ReloadStatusTable[[#This Row],[MSO]],"-",IF(ReloadStatusTable[[#This Row],[Abbreviation]]="HSB","HSE",IF(ReloadStatusTable[[#This Row],[Abbreviation]]="OJB","JOB",ReloadStatusTable[[#This Row],[Abbreviation]])),"-DLY") -> VAN-INFOCAST-NDW-DEN-OAJ-DLY | L22: N/A | M22: N/A | N22: =IF(ReloadStatusTable[[#This Row],[DWH Infocast Jobname]]="N/A","N/A",IF(ReloadStatusTable[[#This Row],[DWH Infocast File Actual Delivery Time (MT)]]="","not delivered yet","Delivered")) -> not delivered yet | O22: =IF(ReloadStatusTable[[#This Row],[DWH Infocast Jobname]]="N/A","N/A",IF(AND(_xlfn.XLOOKUP(ReloadStatusTable[[#This Row],[DWH Infocast Jobname]],'Infocast Autosys Job status'!B:B,'Infocast Autosys Job status'!F:F,"",0)>($C$1 + (18/24)),_xlfn.XLOOKUP(ReloadStatusTable[[#This Row],[DWH Infocast Jobname]],'Infocast Autosys Job status'!B:B,'Infocast Autosys Job status'!F:F,"",0)<($C$1 + 1 + (18/24))),_xlfn.XLOOKUP(ReloadStatusTable[[#This Row],[DWH Infocast Jobname]],'Infocast Autosys Job status'!B:B,'Infocast Autosys Job status'!F:F,"",0),"")) | P22: =ReloadStatusTable[[#This Row],[DWH Infocast File Actual Delivery Time (MT)]] + 1/24 -> #VALUE!
A23: SLC | B23: ACP ORDER/JOB AUDIT | C23: OAJ | D23: =_xlfn.TEXTJOIN("",TRUE, "VIP",ReloadStatusTable[[#This Row],[Abbreviation]],"T") -> VIPOAJT | E23: OAJ_AUDIT | F23: 44238.896 | G23: =ReloadStatusTable[[#This Row],[Forecasted Reload Completion Time (MT)]]+1/24 -> 44238.938 | H23: =IF(ReloadStatusTable[[#This Row],[Actual Completion time (MT)]]="","not done yet","Complete") -> not done yet | I23: =_xlfn.XLOOKUP(CONCATENATE(ReloadStatusTable[[#This Row],[Table]],TEXT(Process_Date,"yyyy-mm-dd")),'Daily_Completion Status'!F:F,'Daily_Completion Status'!H:H,"",0) | J23: =ReloadStatusTable[[#This Row],[Actual Completion time (MT)]]+1/24 -> #VALUE! | K23: =_xlfn.TEXTJOIN("",TRUE, "VAN-INFOCAST-NDW-",ReloadStatusTable[[#This Row],[MSO]],"-",IF(ReloadStatusTable[[#This Row],[Abbreviation]]="HSB","HSE",IF(ReloadStatusTable[[#This Row],[Abbreviation]]="OJB","JOB",ReloadStatusTable[[#This Row],[Abbreviation]])),"-DLY") -> VAN-INFOCAST-NDW-SLC-OAJ-DLY | L23: N/A | M23: N/A | N23: =IF(ReloadStatusTable[[#This Row],[DWH Infocast Jobname]]="N/A","N/A",IF(ReloadStatusTable[[#This Row],[DWH Infocast File Actual Delivery Time (MT)]]="","not delivered yet","Delivered")) -> not delivered yet | O23: =IF(ReloadStatusTable[[#This Row],[DWH Infocast Jobname]]="N/A","N/A",IF(AND(_xlfn.XLOOKUP(ReloadStatusTable[[#This Row],[DWH Infocast Jobname]],'Infocast Autosys Job status'!B:B,'Infocast Autosys Job status'!F:F,"",0)>($C$1 + (18/24)),_xlfn.XLOOKUP(ReloadStatusTable[[#This Row],[DWH Infocast Jobname]],'Infocast Autosys Job status'!B:B,'Infocast Autosys Job status'!F:F,"",0)<($C$1 + 1 + (18/24))),_xlfn.XLOOKUP(ReloadStatusTable[[#This Row],[DWH Infocast Jobname]],'Infocast Autosys Job status'!B:B,'Infocast Autosys Job status'!F:F,"",0),"")) | P23: =ReloadStatusTable[[#This Row],[DWH Infocast File Actual Delivery Time (MT)]] + 1/24 -> #VALUE!
A24: WOM | B24: ACP ORDER/JOB AUDIT | C24: OAJ | D24: =_xlfn.TEXTJOIN("",TRUE, "VIP",ReloadStatusTable[[#This Row],[Abbreviation]],"T") -> VIPOAJT | E24: OAJ_AUDIT | F24: 44238.896 | G24: =ReloadStatusTable[[#This Row],[Forecasted Reload Completion Time (MT)]]+1/24 -> 44238.938 | H24: =IF(ReloadStatusTable[[#This Row],[Actual Completion time (MT)]]="","not done yet","Complete") -> not done yet | I24: =_xlfn.XLOOKUP(CONCATENATE(ReloadStatusTable[[#This Row],[Table]],TEXT(Process_Date,"yyyy-mm-dd")),'Daily_Completion Status'!F:F,'Daily_Completion Status'!H:H,"",0) | J24: =ReloadStatusTable[[#This Row],[Actual Completion time (MT)]]+1/24 -> #VALUE! | K24: =_xlfn.TEXTJOIN("",TRUE, "VAN-INFOCAST-NDW-",ReloadStatusTable[[#This Row],[MSO]],"-",IF(ReloadStatusTable[[#This Row],[Abbreviation]]="HSB","HSE",IF(ReloadStatusTable[[#This Row],[Abbreviation]]="OJB","JOB",ReloadStatusTable[[#This Row],[Abbreviation]])),"-DLY") -> VAN-INFOCAST-NDW-WOM-OAJ-DLY | L24: N/A | M24: N/A | N24: =IF(ReloadStatusTable[[#This Row],[DWH Infocast Jobname]]="N/A","N/A",IF(ReloadStatusTable[[#This Row],[DWH Infocast File Actual Delivery Time (MT)]]="","not delivered yet","Delivered")) -> not delivered yet | O24: =IF(ReloadStatusTable[[#This Row],[DWH Infocast Jobname]]="N/A","N/A",IF(AND(_xlfn.XLOOKUP(ReloadStatusTable[[#This Row],[DWH Infocast Jobname]],'Infocast Autosys Job status'!B:B,'Infocast Autosys Job status'!F:F,"",0)>($C$1 + (18/24)),_xlfn.XLOOKUP(ReloadStatusTable[[#This Row],[DWH Infocast Jobname]],'Infocast Autosys Job status'!B:B,'Infocast Autosys Job status'!F:F,"",0)<($C$1 + 1 + (18/24))),_xlfn.XLOOKUP(ReloadStatusTable[[#This Row],[DWH Infocast Jobname]],'Infocast Autosys Job status'!B:B,'Infocast Autosys Job status'!F:F,"",0),"")) | P24: =ReloadStatusTable[[#This Row],[DWH Infocast File Actual Delivery Time (MT)]] + 1/24 -> #VALUE!
A25: DEN | B25: ACP ORDER/JOB AUDIT | C25: OAO | D25: =_xlfn.TEXTJOIN("",TRUE, "VIP",ReloadStatusTable[[#This Row],[Abbreviation]],"T") -> VIPOAOT | E25: OAO_AUDIT | F25: 44238.896 | G25: =ReloadStatusTable[[#This Row],[Forecasted Reload Completion Time (MT)]]+1/24 -> 44238.938 | H25: =IF(ReloadStatusTable[[#This Row],[Actual Completion time (MT)]]="","not done yet","Complete") -> not done yet | I25: =_xlfn.XLOOKUP(CONCATENATE(ReloadStatusTable[[#This Row],[Table]],TEXT(Process_Date,"yyyy-mm-dd")),'Daily_Completion Status'!F:F,'Daily_Completion Status'!H:H,"",0) | J25: =ReloadStatusTable[[#This Row],[Actual Completion time (MT)]]+1/24 -> #VALUE! | K25: =_xlfn.TEXTJOIN("",TRUE, "VAN-INFOCAST-NDW-",ReloadStatusTable[[#This Row],[MSO]],"-",IF(ReloadStatusTable[[#This Row],[Abbreviation]]="HSB","HSE",IF(ReloadStatusTable[[#This Row],[Abbreviation]]="OJB","JOB",ReloadStatusTable[[#This Row],[Abbreviation]])),"-DLY") -> VAN-INFOCAST-NDW-DEN-OAO-DLY | L25: N/A | M25: N/A | N25: =IF(ReloadStatusTable[[#This Row],[DWH Infocast Jobname]]="N/A","N/A",IF(ReloadStatusTable[[#This Row],[DWH Infocast File Actual Delivery Time (MT)]]="","not delivered yet","Delivered")) -> not delivered yet | O25: =IF(ReloadStatusTable[[#This Row],[DWH Infocast Jobname]]="N/A","N/A",IF(AND(_xlfn.XLOOKUP(ReloadStatusTable[[#This Row],[DWH Infocast Jobname]],'Infocast Autosys Job status'!B:B,'Infocast Autosys Job status'!F:F,"",0)>($C$1 + (18/24)),_xlfn.XLOOKUP(ReloadStatusTable[[#This Row],[DWH Infocast Jobname]],'Infocast Autosys Job status'!B:B,'Infocast Autosys Job status'!F:F,"",0)<($C$1 + 1 + (18/24))),_xlfn.XLOOKUP(ReloadStatusTable[[#This Row],[DWH Infocast Jobname]],'Infocast Autosys Job status'!B:B,'Infocast Autosys Job status'!F:F,"",0),"")) | P25: =ReloadStatusTable[[#This Row],[DWH Infocast File Actual Delivery Time (MT)]] + 1/24 -> #VALUE!
A26: SLC | B26: ACP ORDER/JOB AUDIT | C26: OAO | D26: =_xlfn.TEXTJOIN("",TRUE, "VIP",ReloadStatusTable[[#This Row],[Abbreviation]],"T") -> VIPOAOT | E26: OAO_AUDIT | F26: 44238.896 | G26: =ReloadStatusTable[[#This Row],[Forecasted Reload Completion Time (MT)]]+1/24 -> 44238.938 | H26: =IF(ReloadStatusTable[[#This Row],[Actual Completion time (MT)]]="","not done yet","Complete") -> not done yet | I26: =_xlfn.XLOOKUP(CONCATENATE(ReloadStatusTable[[#This Row],[Table]],TEXT(Process_Date,"yyyy-mm-dd")),'Daily_Completion Status'!F:F,'Daily_Completion Status'!H:H,"",0) | J26: =ReloadStatusTable[[#This Row],[Actual Completion time (MT)]]+1/24 -> #VALUE! | K26: =_xlfn.TEXTJOIN("",TRUE, "VAN-INFOCAST-NDW-",ReloadStatusTable[[#This Row],[MSO]],"-",IF(ReloadStatusTable[[#This Row],[Abbreviation]]="HSB","HSE",IF(ReloadStatusTable[[#This Row],[Abbreviation]]="OJB","JOB",ReloadStatusTable[[#This Row],[Abbreviation]])),"-DLY") -> VAN-INFOCAST-NDW-SLC-OAO-DLY | L26: N/A | M26: N/A | N26: =IF(ReloadStatusTable[[#This Row],[DWH Infocast Jobname]]="N/A","N/A",IF(ReloadStatusTable[[#This Row],[DWH Infocast File Actual Delivery Time (MT)]]="","not delivered yet","Delivered")) -> not delivered yet | O26: =IF(ReloadStatusTable[[#This Row],[DWH Infocast Jobname]]="N/A","N/A",IF(AND(_xlfn.XLOOKUP(ReloadStatusTable[[#This Row],[DWH Infocast Jobname]],'Infocast Autosys Job status'!B:B,'Infocast Autosys Job status'!F:F,"",0)>($C$1 + (18/24)),_xlfn.XLOOKUP(ReloadStatusTable[[#This Row],[DWH Infocast Jobname]],'Infocast Autosys Job status'!B:B,'Infocast Autosys Job status'!F:F,"",0)<($C$1 + 1 + (18/24))),_xlfn.XLOOKUP(ReloadStatusTable[[#This Row],[DWH Infocast Jobname]],'Infocast Autosys Job status'!B:B,'Infocast Autosys Job status'!F:F,"",0),"")) | P26: =ReloadStatusTable[[#This Row],[DWH Infocast File Actual Delivery Time (MT)]] + 1/24 -> #VALUE!
